2025-07-17 12:23:45,680 [INFO] \U0001f680 START SYNC PROCESS
2025-07-17 12:23:45,682 [INFO] \u27a1 Start script: workingfile_to_overview.py
2025-07-17 12:23:48,130 [INFO] Bestand overschreven: C:\Users\bram.gerrits\Desktop\Automations\ProjectAdministration\Output\Overzicht_Projectadministratie_Week29_2025.xlsx
Gewijzigde celwaarden: 2269

2025-07-17 12:23:48,130 [INFO] \u2705 Script workingfile_to_overview.py succesvol afgerond.
2025-07-17 12:23:48,130 [INFO] \u27a1 Start script: read_latest_input.py
2025-07-17 12:23:48,232 [ERROR] \u274c Fout in script: read_latest_input.py
2025-07-17 12:23:48,235 [ERROR] 
2025-07-17 12:23:48,236 [ERROR] python: can't open file 'C:\\Users\\bram.gerrits\\Desktop\\Automations\\ProjectAdministration\\Scripts\\Subs\\read_latest_input.py': [Errno 2] No such file or directory

2025-07-17 12:23:48,236 [ERROR] \u274c Er is een fout opgetreden tijdens het sync-proces.
Traceback (most recent call last):
  File "C:\Users\bram.gerrits\Desktop\Automations\ProjectAdministration\Scripts\sync.py", line 61, in main
    run_script("read_latest_input.py")
    ~~~~~~~~~~^^^^^^^^^^^^^^^^^^^^^^^^
  File "C:\Users\bram.gerrits\Desktop\Automations\ProjectAdministration\Scripts\sync.py", line 38, in run_script
    result = subprocess.run(
        ["python", path],
    ...<2 lines>...
        check=True
    )
  File "C:\Users\bram.gerrits\AppData\Local\Programs\Python\Python313\Lib\subprocess.py", line 579, in run
    raise CalledProcessError(retcode, process.args,
                             output=stdout, stderr=stderr)
subprocess.CalledProcessError: Command '['python', 'C:\\Users\\bram.gerrits\\Desktop\\Automations\\ProjectAdministration\\Scripts\\Subs\\read_latest_input.py']' returned non-zero exit status 2.
